Traceback (most recent call last):
  File "/opt/hostedtoolcache/Python/3.10.5/x64/lib/python3.10/site-packages/jupyter_cache/executors/utils.py", line 51, in single_nb_execution
    executenb(
  File "/opt/hostedtoolcache/Python/3.10.5/x64/lib/python3.10/site-packages/nbclient/client.py", line 1204, in execute
    return NotebookClient(nb=nb, resources=resources, km=km, **kwargs).execute()
  File "/opt/hostedtoolcache/Python/3.10.5/x64/lib/python3.10/site-packages/nbclient/util.py", line 84, in wrapped
    return just_run(coro(*args, **kwargs))
  File "/opt/hostedtoolcache/Python/3.10.5/x64/lib/python3.10/site-packages/nbclient/util.py", line 62, in just_run
    return loop.run_until_complete(coro)
  File "/opt/hostedtoolcache/Python/3.10.5/x64/lib/python3.10/asyncio/base_events.py", line 646, in run_until_complete
    return future.result()
  File "/opt/hostedtoolcache/Python/3.10.5/x64/lib/python3.10/site-packages/nbclient/client.py", line 663, in async_execute
    await self.async_execute_cell(
  File "/opt/hostedtoolcache/Python/3.10.5/x64/lib/python3.10/site-packages/nbclient/client.py", line 965, in async_execute_cell
    await self._check_raise_for_error(cell, cell_index, exec_reply)
  File "/opt/hostedtoolcache/Python/3.10.5/x64/lib/python3.10/site-packages/nbclient/client.py", line 862, in _check_raise_for_error
    raise CellExecutionError.from_cell_and_msg(cell, exec_reply_content)
nbclient.exceptions.CellExecutionError: An error occurred while executing the following cell:
------------------
def gen3peaks(numPoints):
    numPoints/=3
    x1 = np.random.randn(numPoints) * 15 + 100
    x2 = np.random.randn(numPoints) * 10 + 60
    x3 = np.random.randn(numPoints) * 5+ 140
    return np.hstack((x1,x2, x3))

# using 3 peaks for more features and also avoids 
# trap of getting good results with normal data

xbig = gen3peaks(9000)
xmed = gen3peaks(900)
xsmall = gen3peaks(90)
------------------

[0;31m---------------------------------------------------------------------------[0m
[0;31mTypeError[0m                                 Traceback (most recent call last)
Input [0;32mIn [2][0m, in [0;36m<cell line: 11>[0;34m()[0m
[1;32m      6[0m     [38;5;28;01mreturn[39;00m np[38;5;241m.[39mhstack((x1,x2, x3))
[1;32m      8[0m [38;5;66;03m# using 3 peaks for more features and also avoids [39;00m
[1;32m      9[0m [38;5;66;03m# trap of getting good results with normal data[39;00m
[0;32m---> 11[0m xbig [38;5;241m=[39m [43mgen3peaks[49m[43m([49m[38;5;241;43m9000[39;49m[43m)[49m
[1;32m     12[0m xmed [38;5;241m=[39m gen3peaks([38;5;241m900[39m)
[1;32m     13[0m xsmall [38;5;241m=[39m gen3peaks([38;5;241m90[39m)

Input [0;32mIn [2][0m, in [0;36mgen3peaks[0;34m(numPoints)[0m
[1;32m      1[0m [38;5;28;01mdef[39;00m [38;5;21mgen3peaks[39m(numPoints):
[1;32m      2[0m     numPoints[38;5;241m/[39m[38;5;241m=[39m[38;5;241m3[39m
[0;32m----> 3[0m     x1 [38;5;241m=[39m [43mnp[49m[38;5;241;43m.[39;49m[43mrandom[49m[38;5;241;43m.[39;49m[43mrandn[49m[43m([49m[43mnumPoints[49m[43m)[49m [38;5;241m*[39m [38;5;241m15[39m [38;5;241m+[39m [38;5;241m100[39m
[1;32m      4[0m     x2 [38;5;241m=[39m np[38;5;241m.[39mrandom[38;5;241m.[39mrandn(numPoints) [38;5;241m*[39m [38;5;241m10[39m [38;5;241m+[39m [38;5;241m60[39m
[1;32m      5[0m     x3 [38;5;241m=[39m np[38;5;241m.[39mrandom[38;5;241m.[39mrandn(numPoints) [38;5;241m*[39m [38;5;241m5[39m[38;5;241m+[39m [38;5;241m140[39m

File [0;32mmtrand.pyx:1246[0m, in [0;36mnumpy.random.mtrand.RandomState.randn[0;34m()[0m

File [0;32mmtrand.pyx:1403[0m, in [0;36mnumpy.random.mtrand.RandomState.standard_normal[0;34m()[0m

File [0;32m_common.pyx:630[0m, in [0;36mnumpy.random._common.cont[0;34m()[0m

[0;31mTypeError[0m: 'float' object cannot be interpreted as an integer
TypeError: 'float' object cannot be interpreted as an integer

